<?xml version="1.0"?>
<robot xmlns:xacro="http://wiki.ros.org/xacro">

<xacro:macro name="dingo_omni" params="prefix">
    <!-- Define materials -->
    <material name="dark_grey">
        <color rgba="0.2 0.2 0.2 1.0"/>
    </material>
    <material name="light_grey">
        <color rgba="0.4 0.4 0.4 1.0"/>
    </material>
    <material name="yellow">
        <color rgba="0.8 0.8 0.0 1.0"/>
    </material>
    <material name="black">
        <color rgba="0.15 0.15 0.15 1.0"/>
    </material>
    <material name="aluminum">
        <color rgba="0.5 0.5 0.5 1"/>
    </material>
    <material name="plastic">
        <color rgba="0.1 0.1 0.1 1"/>
    </material>
    <!-- ============================= -->
    <!-- Omni base link transformation -->
    <!-- ============================= -->
    <link name="${prefix}base_link">
        <inertial>
            <mass value="1.0"/>
            <origin rpy="0 0 0" xyz="0 0 0"/>
            <inertia ixx="1.0" ixy="0.0" ixz="0.0" iyy="1.0" iyz="0.0" izz="1.0"/>
        </inertial>
    </link>
    <link name="${prefix}base_link_x">
        <inertial>
            <mass value="1.0"/>
            <origin rpy="0 0 0" xyz="0 0 0"/>
            <inertia ixx="1.0" ixy="0.0" ixz="0.0" iyy="1.0" iyz="0.0" izz="1.0"/>
        </inertial>
    </link>
    <link name="${prefix}base_link_y">
        <inertial>
            <mass value="1.0"/>
            <origin rpy="0 0 0" xyz="0 0 0"/>
            <inertia ixx="1.0" ixy="0.0" ixz="0.0" iyy="1.0" iyz="0.0" izz="1.0"/>
        </inertial>
    </link>
    <!-- =============================== -->
    <!-- Omni base joints transformation -->
    <!-- =============================== -->
    <joint name="${prefix}omni_joint_x" type="prismatic">
        <safety_controller k_position="100.0" k_velocity="40.0" soft_lower_limit="-500" soft_upper_limit="500"/>
        <parent link="${prefix}base_link"/>
        <child link="${prefix}base_link_x"/>
        <origin rpy="0 0 0" xyz="0 0 0.0"/>
        <axis xyz="1 0 0"/>
        <dynamics damping="100.0"/>
        <limit effort="1000" lower="-10" upper="10" velocity="2" stiffness="1000"/>
    </joint>
    <joint name="${prefix}omni_joint_y" type="prismatic">
        <safety_controller k_position="100.0" k_velocity="40.0" soft_lower_limit="-500" soft_upper_limit="500"/>
        <parent link="${prefix}base_link_x"/>
        <child link="${prefix}base_link_y"/>
        <origin rpy="0 0 0" xyz="0 0 0"/>
        <axis xyz="0 1 0"/>
        <dynamics damping="100.0"/>
        <limit effort="1000" lower="-10" upper="10" velocity="2" stiffness="1000"/>
    </joint>
    <joint name="${prefix}omni_joint_theta" type="revolute">
        <safety_controller k_position="100.0" k_velocity="40.0" soft_lower_limit="-500" soft_upper_limit="500"/>
        <parent link="${prefix}base_link_y"/>
        <child link="${prefix}chassis_link"/>
        <origin rpy="0 0 0" xyz="0 0 0"/>
        <axis xyz="0 0 1"/>
        <dynamics damping="100.0"/>
        <limit effort="1000" lower="-6.283184" upper="6.283184" velocity="2" stiffness="1000"/>
    </joint>

    <!-- =============== -->
    <!--    Robot links -->
    <!-- =============== -->
    <!-- Chassis link -->
    <link name="${prefix}chassis_link">
        <visual>
            <origin rpy="0 0 0" xyz="0 0 0"/>
            <geometry>
                <mesh filename="package://dinova_description/urdf/meshes/base/omni_chassis.dae"/>
            </geometry>
            <material name="dark_grey"/>
        </visual>
        <collision>
            <origin xyz="0 0 0"/>
            <geometry>
                <mesh filename="package://dinova_description/urdf/meshes/base/omni_chassis_collision.stl"/>
            </geometry>
        </collision>
        <inertial>
            <!-- Center of mass -->
            <origin rpy="0 0 0" xyz="0 0 0"/>
            <mass value="14"/>
            <!-- Moments of inertia: ( chassis without wheels ) -->
            <inertia ixx="0.35498" ixy="0" ixz="0" iyy="0.7266" iyz="0" izz="1.0553"/>
        </inertial>
    </link>
    <!-- Front left wheel link -->
    <link name="${prefix}front_left_wheel_link">
        <visual>
            <origin rpy="1.5707963267948966 0 0" xyz="0 0 0"/>
            <geometry>
                <cylinder length="0.05" radius="0.05"/>
            </geometry>
            <material name="black"/>
        </visual>
        <collision>
            <origin rpy="1.5707963267948966 0 0" xyz="0 0 0"/>
            <geometry>
            <cylinder length="0.05" radius="0.05"/>
            </geometry>
        </collision>
        <inertial>
            <origin rpy="0 0 0" xyz="0 0 0"/>
            <mass value="0.4"/>
            <inertia ixx="0.0003234" ixy="0" ixz="0" iyy="0.0003234" iyz="0" izz="0.0004901"/>
        </inertial>
    </link>
    <!-- Front right wheel link -->
    <link name="${prefix}front_right_wheel_link">
        <visual>
            <origin rpy="1.5707963267948966 0 0" xyz="0 0 0"/>
            <geometry>
             <cylinder length="0.05" radius="0.05"/>
            </geometry>
            <material name="black"/>
        </visual>
        <collision>
            <origin rpy="1.5707963267948966 0 0" xyz="0 0 0"/>
            <geometry>
                <cylinder length="0.05" radius="0.05"/>
            </geometry>
        </collision>
        <inertial>
            <origin rpy="0 0 0" xyz="0 0 0"/>
            <mass value="0.4"/>
            <inertia ixx="0.0003234" ixy="0" ixz="0" iyy="0.0003234" iyz="0" izz="0.0004901"/>
        </inertial>
    </link>
    <!-- Rear left wheel link -->
    <link name="${prefix}rear_left_wheel_link">
        <visual>
            <origin rpy="1.5707963267948966 0 0" xyz="0 0 0"/>
            <geometry>
                <cylinder length="0.05" radius="0.05"/>
            </geometry>
            <material name="black"/>
        </visual>
        <collision>
            <origin rpy="1.5707963267948966 0 0" xyz="0 0 0"/>
            <geometry>
                <cylinder length="0.05" radius="0.05"/>
            </geometry>
        </collision>
        <inertial>
            <origin rpy="0 0 0" xyz="0 0 0"/>
            <mass value="0.4"/>
            <inertia ixx="0.0003234" ixy="0" ixz="0" iyy="0.0003234" iyz="0" izz="0.0004901"/>
        </inertial>
    </link>
    <!-- Rear right wheel link -->
    <link name="${prefix}rear_right_wheel_link">
        <visual>
            <origin rpy="1.5707963267948966 0 0" xyz="0 0 0"/>
            <geometry>
                <cylinder length="0.05" radius="0.05"/>
            </geometry>
            <material name="black"/>
        </visual>
        <collision>
            <origin rpy="1.5707963267948966 0 0" xyz="0 0 0"/>
            <geometry>
                <cylinder length="0.05" radius="0.05"/>
            </geometry>
        </collision>
        <inertial>
            <origin rpy="0 0 0" xyz="0 0 0"/>
            <mass value="0.4"/>
            <inertia ixx="0.0003234" ixy="0" ixz="0" iyy="0.0003234" iyz="0" izz="0.0004901"/>
        </inertial>
    </link>
    <!-- Mounting points -->
    <link name="${prefix}front_mount"/>
    <link name="${prefix}front_b_mount"/>
    <link name="${prefix}front_c_mount"/>
    <link name="${prefix}rear_mount"/>
    <link name="${prefix}rear_b_mount"/>
    <link name="${prefix}rear_c_mount"/>
    <link name="${prefix}mid_mount"/>
    <link name="${prefix}front_bumper_mount"/>
    <!-- =============== -->
    <!--   Robot joints -->
    <!-- =============== -->
    <!-- Front right wheel joint -->
    <joint name="${prefix}front_left_wheel" type="fixed">
        <parent link="${prefix}chassis_link"/>
        <child link="${prefix}front_left_wheel_link"/>
        <origin rpy="0 0 0" xyz="0.285 0.2104 0.035145"/>
        <axis xyz="0 1 0"/>
    </joint>
    <!-- Front left wheel joint -->
    <joint name="${prefix}front_right_wheel" type="fixed">
        <parent link="${prefix}chassis_link"/>
        <child link="${prefix}front_right_wheel_link"/>
        <origin rpy="0 0 0" xyz="0.285 -0.2104 0.035145"/>
        <axis xyz="0 1 0"/>
    </joint>
    <!-- Rear left wheel joint -->
    <joint name="${prefix}rear_left_wheel" type="fixed">
        <parent link="${prefix}chassis_link"/>
        <child link="${prefix}rear_left_wheel_link"/>
        <origin rpy="0 0 0" xyz="-0.285 0.2104 0.035145"/>
        <axis xyz="0 1 0"/>
    </joint>
    <!-- Rear right wheel joint -->
    <joint name="${prefix}rear_right_wheel" type="fixed">
        <parent link="${prefix}chassis_link"/>
        <child link="${prefix}rear_right_wheel_link"/>
        <origin rpy="0 0 0" xyz="-0.285 -0.2104 0.035145"/>
        <axis xyz="0 1 0"/>
    </joint>
    <!-- Mounting points joints -->
    <joint name="${prefix}mid_mount_joint" type="fixed">
        <origin rpy="0 0 0" xyz="0 0 0.069023"/>
        <parent link="${prefix}chassis_link"/>
        <child link="${prefix}mid_mount"/>
    </joint>
        <joint name="${prefix}front_c_mount_joint" type="fixed">
        <origin rpy="0 0 0" xyz="0.080 0 0"/>
        <parent link="${prefix}mid_mount"/>
        <child link="${prefix}front_c_mount"/>
    </joint>
    <joint name="${prefix}front_b_mount_joint" type="fixed">
        <origin rpy="0 0 0" xyz="0.080 0 0"/>
        <parent link="${prefix}front_c_mount"/>
        <child link="${prefix}front_b_mount"/>
    </joint>
    <joint name="${prefix}front_mount_joint" type="fixed">
        <origin rpy="0 0 0" xyz="0.080 0 0"/>
        <parent link="${prefix}front_b_mount"/>
        <child link="${prefix}front_mount"/>
    </joint>
    <joint name="${prefix}rear_c_mount_joint" type="fixed">
        <origin rpy="0 0 0" xyz="-0.080 0 0"/>
        <parent link="${prefix}mid_mount"/>
        <child link="${prefix}rear_c_mount"/>
    </joint>
    <joint name="${prefix}rear_b_mount_joint" type="fixed">
        <origin rpy="0 0 0" xyz="-0.080 0 0"/>
        <parent link="${prefix}rear_c_mount"/>
        <child link="${prefix}rear_b_mount"/>
    </joint>
    <joint name="${prefix}rear_moint_joint" type="fixed">
        <origin rpy="0 0 0" xyz="-0.080 0 0"/>
        <parent link="${prefix}rear_b_mount"/>
        <child link="${prefix}rear_mount"/>
    </joint>
    <joint name="${prefix}front_bumper_mount_joint" type="fixed">
        <origin rpy="0 0 0" xyz="0.34159 0 0.0345115"/>
        <parent link="${prefix}chassis_link"/>
        <child link="${prefix}front_bumper_mount"/>
    </joint>
</xacro:macro>


</robot>