<?xml version="1.0"?>
<robot xmlns:xacro="http://wiki.ros.org/xacro">

<xacro:macro name="kinova" params="prefix">
    <!-- ========== -->
    <!--    LINKS   -->
    <!-- ========== -->
    <!-- ARM base link -->
    <link name="${prefix}kinova_base_link">
        <inertial>
            <origin rpy="0 0 0" xyz="0.00244324 0.00015573 0.08616742"/>
            <mass value="1.14608471"/>
            <inertia ixx="0.00335854" ixy="3.9E-07" ixz="0.00010989" iyy="0.003311" iyz="1.91E-06" izz="0.00077158"/>
        </inertial>
        <visual>
            <origin rpy="0 0 0" xyz="0 0 0"/>
            <geometry>
                <mesh filename="package://dinova_description/urdf/meshes/kinova/base_link.STL"/>
            </geometry>
            <material name="">
                <color rgba="0.803 0.824 0.820 1"/>
            </material>
        </visual>
        <collision>
            <origin rpy="0 0 0" xyz="0 0 0"/>
            <geometry>
                <mesh filename="package://dinova_description/urdf/meshes/kinova/base_link.STL"/>
            </geometry>
        </collision>
    </link>
    <!-- Shoulder link -->
    <link name="${prefix}shoulder_link">
        <inertial>
            <origin xyz="2.477E-05 0.02213531 0.09937686" rpy="0 0 0" />
            <mass value="0.95974404" />
            <inertia ixx="0.00165947" ixy="2E-08" ixz="3.6E-07" iyy="0.00140355" iyz="0.00034927" izz="0.00089493" />
        </inertial>
        <visual>
            <origin xyz="0 0 0" rpy="0 0 0" />
            <geometry>
                <mesh filename="package://dinova_description/urdf/meshes/kinova/shoulder_link.STL"/>
            </geometry>
            <material name="">
                <color rgba="0.803 0.824 0.820 1" />
            </material>
        </visual>
        <collision>
            <origin xyz="0 0 0" rpy="0 0 0" />
            <geometry>
                <mesh filename="package://dinova_description/urdf/meshes/kinova/shoulder_link.STL"/>
            </geometry>
        </collision>
    </link>
    <!-- Arm link -->
    <link name="${prefix}arm_link">
        <inertial>
            <origin xyz="0.02998299 0.21154808 0.0453031" rpy="0 0 0" />
            <mass value="1.17756164" />
            <inertia ixx="0.01149277" ixy="1E-06" ixz="1.6E-07" iyy="0.00102851" iyz="0.00140765" izz="0.01133492" />
        </inertial>
        <visual>
            <origin xyz="0 0 0" rpy="0 0 0" />
            <geometry>
                <mesh filename="package://dinova_description/urdf/meshes/kinova/arm_link.STL"/>
            </geometry>
            <material name="">
                <color rgba="0.803 0.824 0.820 1" />
            </material>
        </visual>
        <collision>
            <origin xyz="0 0 0" rpy="0 0 0" />
            <geometry>
                <mesh filename="package://dinova_description/urdf/meshes/kinova/arm_link.STL"/>
            </geometry>
        </collision>
    </link>
    <!-- Forearm link -->
    <link name="${prefix}forearm_link">
        <inertial>
            <origin xyz="0.0301559 0.09502206 0.0073555" rpy="0 0 0" />
            <mass value="0.59767669" />
            <inertia ixx="0.00163256" ixy="7.11E-06" ixz="1.54E-06" iyy="0.00029798" iyz="9.587E-05" izz="0.00169091" />
        </inertial>
        <visual>
            <origin xyz="0 0 0" rpy="0 0 0" />
            <geometry>
                <mesh filename="package://dinova_description/urdf/meshes/kinova/forearm_link.STL"/>
            </geometry>
            <material name="">
                <color rgba="0.803 0.824 0.820 1" />
            </material>
        </visual>
        <collision>
            <origin xyz="0 0 0" rpy="0 0 0" />
            <geometry>
                <mesh filename="package://dinova_description/urdf/meshes/kinova/forearm_link.STL"/>
            </geometry>
        </collision>
    </link>
    <!-- Lower_wrist_link  -->
    <link name="${prefix}lower_wrist_link">
        <inertial>
            <origin xyz="0.00575149 0.01000443 0.08719207" rpy="0 0 0" />
            <mass value="0.52693412" />
            <inertia ixx="0.00069098" ixy="2.4E-07" ixz="0.00016483" iyy="0.00078519" iyz="7.4E-07" izz="0.00034115" />
        </inertial>
        <visual>
            <origin xyz="0 0 0" rpy="0 0 0" />
            <geometry>
                <mesh filename="package://dinova_description/urdf/meshes/kinova/lower_wrist_link.STL"/>
            </geometry>
            <material name="">
                <color rgba="0.803 0.824 0.820 1" />
            </material>
        </visual>
        <collision>
            <origin xyz="0 0 0" rpy="0 0 0" />
            <geometry>
                <mesh filename="package://dinova_description/urdf/meshes/kinova/lower_wrist_link.STL"/>
            </geometry>
        </collision>
    </link>
    <!-- Upper_wrist_link -->
    <link name="${prefix}upper_wrist_link">
        <inertial>
            <origin xyz="0.08056517 0.00980409 0.01872799" rpy="0 0 0" />
            <mass value="0.58097325" />
            <inertia ixx="0.00021268" ixy="5.21E-06" ixz="2.91E-06" iyy="0.00106371" iyz="1.1E-07" izz="0.00108465" />
        </inertial>
        <visual>
            <origin xyz="0 0 0" rpy="0 0 0" />
            <geometry>
                <mesh filename="package://dinova_description/urdf/meshes/kinova/upper_wrist_link.STL"/>
            </geometry>
            <material name="">
                <color rgba="0.803 0.824 0.820 1" />
            </material>
        </visual>
        <collision>
            <origin xyz="0 0 0" rpy="0 0 0" />
            <geometry>
                <mesh filename="package://dinova_description/urdf/meshes/kinova/upper_wrist_link.STL"/>
            </geometry>
        </collision>
    </link>
    <!-- Dummy links for transforming axes -->
    <link name="${prefix}end_effector_link">
        <inertial>
            <mass value="0.0001"/>
            <origin rpy="0 0 0" xyz="0 0 0"/>
            <inertia ixx="0.0001" ixy="0.0" ixz="0.0" iyy="0.0001" iyz="0.0" izz="0.0001"/>
        </inertial>
    </link>
    <link name="${prefix}dummy_link" />
    <link name="${prefix}tool_frame"/>

    


    <!-- ================= -->
    <!-- Revolute JOINTS   -->
    <!-- ================= -->
    <!-- Joint 1 -->
    <joint name="${prefix}joint_1" type="revolute">
        <origin rpy="-2.746893142615157e-05 -0.0012876966269176834 -3.4078623335807743e-16" xyz="-1.8836019394079857e-16 -3.688218839160853e-17 0.12825000000000078" />
        <parent link="${prefix}kinova_base_link" />
        <child link="${prefix}shoulder_link" />
        <axis xyz="0 0 1" />
        <limit lower="-2.68" upper="2.68" effort="10" velocity="1.6" />
    </joint>
    <!-- Joint 2 -->
    <joint name="${prefix}joint_2" type="revolute">
        <origin rpy="1.581263130895373 0.015120261949270858 1.5164839538784716e-05" xyz="-0.0005014484308504022 -0.029343454485041668 0.11500000000000155" />
        <parent link="${prefix}shoulder_link" />
        <child link="${prefix}arm_link" />
        <axis xyz="0 0 1" />
        <limit lower="-2.61" upper="2.61" effort="14" velocity="1.6" />
    </joint>
    <!-- Joint 3 -->
    <joint name="${prefix}joint_3" type="revolute">
        <origin rpy="-3.1460688147415032 -0.013928343995075362 -0.01397495853756151" xyz="0.004095913096920563 0.28293673179772627 -0.0006561462132585497" />
        <parent link="${prefix}arm_link" />
        <child link="${prefix}forearm_link" />
        <axis xyz="0 0 1" />
        <limit lower="-2.61" upper="2.61" effort="10" velocity="1.6" />
    </joint>
    <!-- Joint 4 -->
    <joint name="${prefix}joint_4" type="revolute">
        <origin rpy="1.570135251499924 0.00020755089686141798 0.013771183766511014" xyz="0.001465691695560486 -0.1409451077317066 0.020698873181334607" />
        <parent link="${prefix}forearm_link" />
        <child link="${prefix}lower_wrist_link" />
        <axis xyz="0 0 1" />
        <limit lower="-2.57" upper="2.57" effort="39" velocity="1.3963" />
    </joint>
    <!-- Joint 5 -->
    <joint name="${prefix}joint_5" type="revolute">
        <origin rpy="0.00016848106903807688 1.566674528420962 -0.0001763473975477907" xyz="0.028307136985665976 -0.0007740663723995084 0.1059664426831494" />
        <parent link="${prefix}lower_wrist_link" />
        <child link="${prefix}upper_wrist_link" />
        <axis xyz="0 0 1" />
        <limit lower="-2.53" upper="2.53" effort="7" velocity="1.6" />
    </joint>
    <!-- Joint 6 -->
    <joint name="${prefix}joint_6" type="revolute">
        <origin rpy="-0.0016434779097823941 -1.5685481245804054 -0.0016434820817590162" xyz="-0.111504270439627 0.002536337273228278 0.02831137395835149" />
        <parent link="${prefix}upper_wrist_link" />
        <child link="${prefix}end_effector_link" />
        <axis xyz="0 0 1" />
        <limit lower="-2.09" upper="2.09" effort="9" velocity="1.2218" />
    </joint>

    <!-- ================= -->
    <!-- Fixed JOINTS      -->
    <!-- ================= -->
    <joint name="${prefix}end_effector" type="fixed">
        <origin xyz="0 0 0" rpy="0 0 0" />
        <parent link="${prefix}end_effector_link" />
        <child link="${prefix}dummy_link" />
        <axis xyz="0 0 1" />
        <limit lower="0" upper="0" effort="0" velocity="0" />
    </joint>
    <!-- Tool frame used by the arm -->
   <joint name="${prefix}tool_frame_joint" type="fixed">
        <origin rpy="0 0 0" xyz="0 0 0.07"/>
        <parent link="${prefix}dummy_link"/>
        <child link="${prefix}tool_frame"/>
        <axis xyz="0 0 0"/>
    </joint>
   
</xacro:macro>


</robot>